[0m16:35:33.251350 [debug] [MainThread]: Sending event: {'category': 'dbt', 'action': 'invocation', 'label': 'start', 'context': [<snowplow_tracker.self_describing_json.SelfDescribingJson object at 0x105593be0>, <snowplow_tracker.self_describing_json.SelfDescribingJson object at 0x1064a1f60>, <snowplow_tracker.self_describing_json.SelfDescribingJson object at 0x1064a1b10>]}


============================== 16:35:33.254068 | c18d335a-966b-4321-b8ce-b6bff1c0694a ==============================
[0m16:35:33.254068 [info ] [MainThread]: Running with dbt=1.9.2
[0m16:35:33.254432 [debug] [MainThread]: running dbt with arguments {'printer_width': '80', 'indirect_selection': 'eager', 'write_json': 'True', 'log_cache_events': 'False', 'partial_parse': 'True', 'cache_selected_only': 'False', 'profiles_dir': '/Users/hugodecourcelle/.dbt', 'fail_fast': 'False', 'warn_error': 'None', 'log_path': 'logs', 'debug': 'False', 'version_check': 'True', 'use_colors': 'True', 'use_experimental_parser': 'False', 'no_print': 'None', 'quiet': 'False', 'empty': 'None', 'log_format': 'default', 'introspect': 'True', 'warn_error_options': 'WarnErrorOptions(include=[], exclude=[])', 'invocation_command': 'dbt init my_velib_dbt_project', 'target_path': 'None', 'static_parser': 'True', 'send_anonymous_usage_stats': 'True'}
[0m16:35:33.262202 [debug] [MainThread]: Starter project path: /Users/hugodecourcelle/.pyenv/versions/velib_env/lib/python3.10/site-packages/dbt/include/starter_project
[0m16:35:33.266275 [info ] [MainThread]: 
Your new dbt project "my_velib_dbt_project" was created!

For more information on how to configure the profiles.yml file,
please consult the dbt documentation here:

  https://docs.getdbt.com/docs/configure-your-profile

One more thing:

Need help? Don't hesitate to reach out to us via GitHub issues or on Slack:

  https://community.getdbt.com/

Happy modeling!

[0m16:35:33.266533 [info ] [MainThread]: Setting up your profile.
[0m16:41:26.854287 [error] [MainThread]: Encountered an error:

[0m16:41:26.860750 [error] [MainThread]: Traceback (most recent call last):
  File "/Users/hugodecourcelle/.pyenv/versions/velib_env/lib/python3.10/site-packages/dbt/cli/requires.py", line 153, in wrapper
    result, success = func(*args, **kwargs)
  File "/Users/hugodecourcelle/.pyenv/versions/velib_env/lib/python3.10/site-packages/dbt/cli/requires.py", line 103, in wrapper
    return func(*args, **kwargs)
  File "/Users/hugodecourcelle/.pyenv/versions/velib_env/lib/python3.10/site-packages/dbt/cli/main.py", line 477, in init
    results = task.run()
  File "/Users/hugodecourcelle/.pyenv/versions/velib_env/lib/python3.10/site-packages/dbt/task/init.py", line 346, in run
    self.setup_profile(profile_name)
  File "/Users/hugodecourcelle/.pyenv/versions/velib_env/lib/python3.10/site-packages/dbt/task/init.py", line 262, in setup_profile
    self.create_profile_from_target(adapter, profile_name=profile_name)
  File "/Users/hugodecourcelle/.pyenv/versions/velib_env/lib/python3.10/site-packages/dbt/task/init.py", line 179, in create_profile_from_target
    self.create_profile_from_profile_template(profile_template, profile_name)
  File "/Users/hugodecourcelle/.pyenv/versions/velib_env/lib/python3.10/site-packages/dbt/task/init.py", line 163, in create_profile_from_profile_template
    target = self.generate_target_from_input(prompts, initial_target)
  File "/Users/hugodecourcelle/.pyenv/versions/velib_env/lib/python3.10/site-packages/dbt/task/init.py", line 129, in generate_target_from_input
    target[key] = click.prompt(
  File "/Users/hugodecourcelle/.pyenv/versions/velib_env/lib/python3.10/site-packages/click/termui.py", line 164, in prompt
    value = prompt_func(prompt)
  File "/Users/hugodecourcelle/.pyenv/versions/velib_env/lib/python3.10/site-packages/click/termui.py", line 147, in prompt_func
    raise Abort() from None
click.exceptions.Abort

[0m16:41:26.864967 [debug] [MainThread]: Resource report: {"command_name": "init", "command_success": false, "command_wall_clock_time": 353.64792, "process_in_blocks": "0", "process_kernel_time": 0.18304, "process_mem_max_rss": "178536448", "process_out_blocks": "0", "process_user_time": 1.047485}
[0m16:41:26.865510 [debug] [MainThread]: Command `dbt init` failed at 16:41:26.865421 after 353.65 seconds
[0m16:41:26.866108 [debug] [MainThread]: Sending event: {'category': 'dbt', 'action': 'invocation', 'label': 'end', 'context': [<snowplow_tracker.self_describing_json.SelfDescribingJson object at 0x105593be0>, <snowplow_tracker.self_describing_json.SelfDescribingJson object at 0x10d04e530>, <snowplow_tracker.self_describing_json.SelfDescribingJson object at 0x10d04e140>]}
[0m16:41:26.867124 [debug] [MainThread]: Flushing usage events
[0m16:41:27.293429 [debug] [MainThread]: An error was encountered while trying to flush usage events
[0m16:41:37.878214 [debug] [MainThread]: Sending event: {'category': 'dbt', 'action': 'invocation', 'label': 'start', 'context': [<snowplow_tracker.self_describing_json.SelfDescribingJson object at 0x102edfc10>, <snowplow_tracker.self_describing_json.SelfDescribingJson object at 0x103de9ff0>, <snowplow_tracker.self_describing_json.SelfDescribingJson object at 0x103de9ba0>]}


============================== 16:41:37.880786 | 1c5d8d48-7ff2-43a4-8508-b1c35eed32dc ==============================
[0m16:41:37.880786 [info ] [MainThread]: Running with dbt=1.9.2
[0m16:41:37.881144 [debug] [MainThread]: running dbt with arguments {'printer_width': '80', 'indirect_selection': 'eager', 'write_json': 'True', 'log_cache_events': 'False', 'partial_parse': 'True', 'cache_selected_only': 'False', 'warn_error': 'None', 'version_check': 'True', 'fail_fast': 'False', 'log_path': 'logs', 'debug': 'False', 'profiles_dir': '/Users/hugodecourcelle/.dbt', 'use_colors': 'True', 'use_experimental_parser': 'False', 'no_print': 'None', 'quiet': 'False', 'empty': 'None', 'log_format': 'default', 'introspect': 'True', 'static_parser': 'True', 'warn_error_options': 'WarnErrorOptions(include=[], exclude=[])', 'target_path': 'None', 'invocation_command': 'dbt init my_velib_dbt_project', 'send_anonymous_usage_stats': 'True'}
[0m16:41:37.904345 [info ] [MainThread]: A project called my_velib_dbt_project already exists here.
[0m16:41:37.909825 [debug] [MainThread]: Resource report: {"command_name": "init", "command_success": true, "command_wall_clock_time": 0.06758241, "process_in_blocks": "0", "process_kernel_time": 0.087, "process_mem_max_rss": "93011968", "process_out_blocks": "0", "process_user_time": 0.631816}
[0m16:41:37.912029 [debug] [MainThread]: Command `dbt init` succeeded at 16:41:37.911121 after 0.07 seconds
[0m16:41:37.913140 [debug] [MainThread]: Sending event: {'category': 'dbt', 'action': 'invocation', 'label': 'end', 'context': [<snowplow_tracker.self_describing_json.SelfDescribingJson object at 0x102edfc10>, <snowplow_tracker.self_describing_json.SelfDescribingJson object at 0x103dea050>, <snowplow_tracker.self_describing_json.SelfDescribingJson object at 0x103deb5b0>]}
[0m16:41:37.913460 [debug] [MainThread]: Flushing usage events
[0m16:41:38.270857 [debug] [MainThread]: An error was encountered while trying to flush usage events
[0m16:44:24.002111 [debug] [MainThread]: Sending event: {'category': 'dbt', 'action': 'invocation', 'label': 'start', 'context': [<snowplow_tracker.self_describing_json.SelfDescribingJson object at 0x105aefb20>, <snowplow_tracker.self_describing_json.SelfDescribingJson object at 0x1074cdf00>, <snowplow_tracker.self_describing_json.SelfDescribingJson object at 0x1074cdab0>]}


============================== 16:44:24.004835 | be2deda1-da89-4c0e-a141-4e67dbb68f39 ==============================
[0m16:44:24.004835 [info ] [MainThread]: Running with dbt=1.9.2
[0m16:44:24.005196 [debug] [MainThread]: running dbt with arguments {'printer_width': '80', 'indirect_selection': 'eager', 'log_cache_events': 'False', 'write_json': 'True', 'partial_parse': 'True', 'cache_selected_only': 'False', 'warn_error': 'None', 'fail_fast': 'False', 'profiles_dir': '/Users/hugodecourcelle/.dbt', 'log_path': 'logs', 'debug': 'False', 'version_check': 'True', 'use_colors': 'True', 'use_experimental_parser': 'False', 'empty': 'None', 'quiet': 'False', 'no_print': 'None', 'warn_error_options': 'WarnErrorOptions(include=[], exclude=[])', 'static_parser': 'True', 'log_format': 'default', 'invocation_command': 'dbt init my_velib_dbt_project', 'target_path': 'None', 'introspect': 'True', 'send_anonymous_usage_stats': 'True'}
[0m16:44:24.012918 [debug] [MainThread]: Starter project path: /Users/hugodecourcelle/.pyenv/versions/velib_env/lib/python3.10/site-packages/dbt/include/starter_project
[0m16:44:24.017323 [info ] [MainThread]: 
Your new dbt project "my_velib_dbt_project" was created!

For more information on how to configure the profiles.yml file,
please consult the dbt documentation here:

  https://docs.getdbt.com/docs/configure-your-profile

One more thing:

Need help? Don't hesitate to reach out to us via GitHub issues or on Slack:

  https://community.getdbt.com/

Happy modeling!

[0m16:44:24.017576 [info ] [MainThread]: Setting up your profile.
[0m16:58:56.818202 [info ] [MainThread]: Profile my_velib_dbt_project written to /Users/hugodecourcelle/.dbt/profiles.yml using target's profile_template.yml and your supplied values. Run 'dbt debug' to validate the connection.
[0m16:58:56.822575 [debug] [MainThread]: Resource report: {"command_name": "init", "command_success": true, "command_wall_clock_time": 872.9057, "process_in_blocks": "0", "process_kernel_time": 0.16862, "process_mem_max_rss": "178438144", "process_out_blocks": "0", "process_user_time": 0.929692}
[0m16:58:56.823359 [debug] [MainThread]: Command `dbt init` succeeded at 16:58:56.823222 after 872.91 seconds
[0m16:58:56.823922 [debug] [MainThread]: Sending event: {'category': 'dbt', 'action': 'invocation', 'label': 'end', 'context': [<snowplow_tracker.self_describing_json.SelfDescribingJson object at 0x105aefb20>, <snowplow_tracker.self_describing_json.SelfDescribingJson object at 0x1074cce50>, <snowplow_tracker.self_describing_json.SelfDescribingJson object at 0x107477b20>]}
[0m16:58:56.824505 [debug] [MainThread]: Flushing usage events
[0m16:58:57.209309 [debug] [MainThread]: An error was encountered while trying to flush usage events
[0m18:21:53.676866 [debug] [MainThread]: Sending event: {'category': 'dbt', 'action': 'invocation', 'label': 'start', 'context': [<snowplow_tracker.self_describing_json.SelfDescribingJson object at 0x103d43be0>, <snowplow_tracker.self_describing_json.SelfDescribingJson object at 0x10577a110>, <snowplow_tracker.self_describing_json.SelfDescribingJson object at 0x105779cc0>]}


============================== 18:21:53.679545 | 652e909a-f7a7-4635-bb9a-d29780d734fe ==============================
[0m18:21:53.679545 [info ] [MainThread]: Running with dbt=1.9.2
[0m18:21:53.680001 [debug] [MainThread]: running dbt with arguments {'printer_width': '80', 'indirect_selection': 'eager', 'write_json': 'True', 'log_cache_events': 'False', 'partial_parse': 'True', 'cache_selected_only': 'False', 'profiles_dir': 'my_velib_dbt_project/.dbt/profiles.yml', 'fail_fast': 'False', 'warn_error': 'None', 'log_path': 'logs', 'debug': 'False', 'version_check': 'True', 'use_colors': 'True', 'use_experimental_parser': 'False', 'empty': 'False', 'quiet': 'False', 'no_print': 'None', 'warn_error_options': 'WarnErrorOptions(include=[], exclude=[])', 'introspect': 'True', 'log_format': 'default', 'invocation_command': 'dbt run --models my_velib_dbt_project.models.test_model_marseille', 'target_path': 'None', 'static_parser': 'True', 'send_anonymous_usage_stats': 'True'}
[0m18:21:53.680361 [error] [MainThread]: Encountered an error:
Runtime Error
  No dbt_project.yml found at expected path /Users/hugodecourcelle/Documents/PYTHON/python_velib/dbt_project.yml
  Verify that each entry within packages.yml (and their transitive dependencies) contains a file named dbt_project.yml
  
[0m18:21:53.681766 [debug] [MainThread]: Resource report: {"command_name": "run", "command_success": false, "command_wall_clock_time": 0.044725083, "process_in_blocks": "0", "process_kernel_time": 0.093608, "process_mem_max_rss": "92241920", "process_out_blocks": "0", "process_user_time": 0.622141}
[0m18:21:53.682052 [debug] [MainThread]: Command `dbt run` failed at 18:21:53.681999 after 0.05 seconds
[0m18:21:53.682264 [debug] [MainThread]: Sending event: {'category': 'dbt', 'action': 'invocation', 'label': 'end', 'context': [<snowplow_tracker.self_describing_json.SelfDescribingJson object at 0x103d43be0>, <snowplow_tracker.self_describing_json.SelfDescribingJson object at 0x105778fa0>, <snowplow_tracker.self_describing_json.SelfDescribingJson object at 0x10577bcd0>]}
[0m18:21:53.682467 [debug] [MainThread]: Flushing usage events
[0m18:21:54.078439 [debug] [MainThread]: An error was encountered while trying to flush usage events
[0m18:23:51.937196 [debug] [MainThread]: Sending event: {'category': 'dbt', 'action': 'invocation', 'label': 'start', 'context': [<snowplow_tracker.self_describing_json.SelfDescribingJson object at 0x1035abc40>, <snowplow_tracker.self_describing_json.SelfDescribingJson object at 0x104476140>, <snowplow_tracker.self_describing_json.SelfDescribingJson object at 0x104475cf0>]}


============================== 18:23:51.939812 | 80e520e9-1118-4044-bb0a-4c1a05b908d0 ==============================
[0m18:23:51.939812 [info ] [MainThread]: Running with dbt=1.9.2
[0m18:23:51.940292 [debug] [MainThread]: running dbt with arguments {'printer_width': '80', 'indirect_selection': 'eager', 'log_cache_events': 'False', 'write_json': 'True', 'partial_parse': 'True', 'cache_selected_only': 'False', 'warn_error': 'None', 'version_check': 'True', 'debug': 'False', 'log_path': 'logs', 'fail_fast': 'False', 'profiles_dir': 'my_velib_dbt_project/.dbt/profiles.yml', 'use_colors': 'True', 'use_experimental_parser': 'False', 'no_print': 'None', 'quiet': 'False', 'empty': 'False', 'log_format': 'default', 'introspect': 'True', 'warn_error_options': 'WarnErrorOptions(include=[], exclude=[])', 'static_parser': 'True', 'target_path': 'None', 'invocation_command': 'dbt run --models my_velib_dbt_project.models.test_model_marseille', 'send_anonymous_usage_stats': 'True'}
[0m18:23:51.940665 [error] [MainThread]: Encountered an error:
Runtime Error
  No dbt_project.yml found at expected path /Users/hugodecourcelle/Documents/PYTHON/python_velib/dbt_project.yml
  Verify that each entry within packages.yml (and their transitive dependencies) contains a file named dbt_project.yml
  
[0m18:23:51.942045 [debug] [MainThread]: Resource report: {"command_name": "run", "command_success": false, "command_wall_clock_time": 0.042031042, "process_in_blocks": "0", "process_kernel_time": 0.090116, "process_mem_max_rss": "92782592", "process_out_blocks": "0", "process_user_time": 0.627751}
[0m18:23:51.942321 [debug] [MainThread]: Command `dbt run` failed at 18:23:51.942268 after 0.04 seconds
[0m18:23:51.942535 [debug] [MainThread]: Sending event: {'category': 'dbt', 'action': 'invocation', 'label': 'end', 'context': [<snowplow_tracker.self_describing_json.SelfDescribingJson object at 0x1035abc40>, <snowplow_tracker.self_describing_json.SelfDescribingJson object at 0x104474fd0>, <snowplow_tracker.self_describing_json.SelfDescribingJson object at 0x104477d00>]}
[0m18:23:51.942749 [debug] [MainThread]: Flushing usage events
[0m18:23:52.342347 [debug] [MainThread]: An error was encountered while trying to flush usage events
[0m18:24:22.743483 [debug] [MainThread]: Sending event: {'category': 'dbt', 'action': 'invocation', 'label': 'start', 'context': [<snowplow_tracker.self_describing_json.SelfDescribingJson object at 0x1039ebc40>, <snowplow_tracker.self_describing_json.SelfDescribingJson object at 0x10537a140>, <snowplow_tracker.self_describing_json.SelfDescribingJson object at 0x105379cf0>]}


============================== 18:24:22.745515 | 26ce65d0-8dae-450a-9762-768b64992f4d ==============================
[0m18:24:22.745515 [info ] [MainThread]: Running with dbt=1.9.2
[0m18:24:22.745974 [debug] [MainThread]: running dbt with arguments {'printer_width': '80', 'indirect_selection': 'eager', 'log_cache_events': 'False', 'write_json': 'True', 'partial_parse': 'True', 'cache_selected_only': 'False', 'profiles_dir': 'my_velib_dbt_project/.dbt/profiles.yml', 'version_check': 'True', 'warn_error': 'None', 'log_path': 'logs', 'fail_fast': 'False', 'debug': 'False', 'use_colors': 'True', 'use_experimental_parser': 'False', 'no_print': 'None', 'quiet': 'False', 'empty': 'False', 'log_format': 'default', 'introspect': 'True', 'warn_error_options': 'WarnErrorOptions(include=[], exclude=[])', 'invocation_command': 'dbt run --models my_velib_dbt_project.models.test_model_marseille', 'target_path': 'None', 'static_parser': 'True', 'send_anonymous_usage_stats': 'True'}
[0m18:24:22.746338 [error] [MainThread]: Encountered an error:
Runtime Error
  No dbt_project.yml found at expected path my_velib_dbt_project/dbt_project.yml/dbt_project.yml
  Verify that each entry within packages.yml (and their transitive dependencies) contains a file named dbt_project.yml
  
[0m18:24:22.747053 [debug] [MainThread]: Resource report: {"command_name": "run", "command_success": false, "command_wall_clock_time": 0.038471833, "process_in_blocks": "0", "process_kernel_time": 0.055822, "process_mem_max_rss": "93175808", "process_out_blocks": "0", "process_user_time": 0.614246}
[0m18:24:22.747320 [debug] [MainThread]: Command `dbt run` failed at 18:24:22.747264 after 0.04 seconds
[0m18:24:22.747536 [debug] [MainThread]: Sending event: {'category': 'dbt', 'action': 'invocation', 'label': 'end', 'context': [<snowplow_tracker.self_describing_json.SelfDescribingJson object at 0x1039ebc40>, <snowplow_tracker.self_describing_json.SelfDescribingJson object at 0x105378fd0>, <snowplow_tracker.self_describing_json.SelfDescribingJson object at 0x10537bd00>]}
[0m18:24:22.747742 [debug] [MainThread]: Flushing usage events
[0m18:24:23.140365 [debug] [MainThread]: An error was encountered while trying to flush usage events
[0m18:27:06.803462 [debug] [MainThread]: Sending event: {'category': 'dbt', 'action': 'invocation', 'label': 'start', 'context': [<snowplow_tracker.self_describing_json.SelfDescribingJson object at 0x105c7fbe0>, <snowplow_tracker.self_describing_json.SelfDescribingJson object at 0x106b4a110>, <snowplow_tracker.self_describing_json.SelfDescribingJson object at 0x106b49cc0>]}


============================== 18:27:06.806029 | 9d2fc6f9-f111-46b8-9c8b-dd76906c65cf ==============================
[0m18:27:06.806029 [info ] [MainThread]: Running with dbt=1.9.2
[0m18:27:06.806470 [debug] [MainThread]: running dbt with arguments {'printer_width': '80', 'indirect_selection': 'eager', 'log_cache_events': 'False', 'write_json': 'True', 'partial_parse': 'True', 'cache_selected_only': 'False', 'profiles_dir': 'my_velib_dbt_project/.dbt/profiles.yml', 'fail_fast': 'False', 'warn_error': 'None', 'log_path': 'logs', 'version_check': 'True', 'debug': 'False', 'use_colors': 'True', 'use_experimental_parser': 'False', 'no_print': 'None', 'quiet': 'False', 'empty': 'False', 'warn_error_options': 'WarnErrorOptions(include=[], exclude=[])', 'introspect': 'True', 'invocation_command': 'dbt run --models my_velib_dbt_project.models.test_model_marseille', 'log_format': 'default', 'target_path': 'None', 'static_parser': 'True', 'send_anonymous_usage_stats': 'True'}
[0m18:27:06.806833 [error] [MainThread]: Encountered an error:
Runtime Error
  No dbt_project.yml found at expected path my_velib_dbt_project/dbt_project.yml/dbt_project.yml
  Verify that each entry within packages.yml (and their transitive dependencies) contains a file named dbt_project.yml
  
[0m18:27:06.807742 [debug] [MainThread]: Resource report: {"command_name": "run", "command_success": false, "command_wall_clock_time": 0.042751294, "process_in_blocks": "0", "process_kernel_time": 0.071511, "process_mem_max_rss": "93536256", "process_out_blocks": "0", "process_user_time": 0.627073}
[0m18:27:06.808021 [debug] [MainThread]: Command `dbt run` failed at 18:27:06.807965 after 0.04 seconds
[0m18:27:06.808245 [debug] [MainThread]: Sending event: {'category': 'dbt', 'action': 'invocation', 'label': 'end', 'context': [<snowplow_tracker.self_describing_json.SelfDescribingJson object at 0x105c7fbe0>, <snowplow_tracker.self_describing_json.SelfDescribingJson object at 0x106b48fa0>, <snowplow_tracker.self_describing_json.SelfDescribingJson object at 0x106b4bcd0>]}
[0m18:27:06.808464 [debug] [MainThread]: Flushing usage events
[0m18:27:07.198850 [debug] [MainThread]: An error was encountered while trying to flush usage events
